Workbook

Sheet Phase Tracker
A1: Phase | B1: Name | C1: Status | D1: Key Deliverable | E1: Key Metric | F1: Result | G1: Blockers | H1: Files / Artifacts | I1: Notes
A2: 1 | B2: CfC/NCP Core | C2: ✅ Done | D2: CfC cell + NCP wiring in JAX | E2: Unit tests | F2: 8/8 passing | G2: — | H2: phase1_cfc_ncp.py | I2: Cross-referenced all v1-v12 failures
A3: 2 | B3: MLP Baseline | C3: ✅ Done | D3: MLP locomotion policy (Brax PPO) | E3: Reward | F3: 11.51 | G3: — | H3: phase2_mlp_baseline.py | I3: Pivoted from custom PPO to MuJoCo Playground
A4: 3a | B4: CfC Locomotion | C4: ✅ Done | D4: CfC policy beats MLP on Go1 | E4: Reward (vs MLP) | F4: 27.4 (2.38x) | G4: — | H4: phase3_cfc_brax_ppo.py | I4: First CfC quadruped locomotion
A5: 3b | B5: Recurrent CfC | C5: ✅ Done | D5: Hidden state carry through PPO | E5: Reward | F5: 26.6 | G5: — | H5: phase3b_complete.py | I5: Normalizer corruption fixed, h evolves
A6: 4 | B6: CBF Safety Layer | C6: ✅ Done | D6: 0th-order CBF with 10kHz proof | E6: Unit tests / freq | F6: 7/7 ✓ / 84kHz | G6: — | H6: phase4_soma_cbf_final.py | I6: HOCBF failed (M too small), static CBF correct for PD joints
A7: 5 | B7: Body-Level CBFs | C7: 🔲 Todo | D7: Roll/pitch limits, min height, CoM | E7: Tip-over prevention | F7: — | G7: Needs Phase 4 env access | H7: — | I7: Compose on top of joint CBF
A8: 6 | B8: Multi-Robot | C8: 🔲 Todo | D8: Train Go1+H1, test A1+Cassie | E8: Zero-shot transfer accuracy | F8: — | G8: Needs H1 env setup | H8: — | I8: Validates 'any-robot URDF' claim
A9: 7 | B9: MoE Integration | C9: 🔲 Todo | D9: 8 Expert CfC + Gate routing | E9: Multi-task reward | F9: — | G9: Needs Phase 6 | H9: — | I9: v11 architecture: Backbone→Gate→Experts→Heads
A10: 8 | B10: Deployment | C10: 🔲 Todo | D10: INT8 quant, AOT export, sub-500KB | E10: Model size / CPU latency | F10: — | G10: Needs Phase 7 | H10: — | I10: C reimplementation of CBF for ARM
A11: 9 | B11: H1 Torque CBF | C11: 🔲 Todo | D11: 2nd-order HOCBF with real M(q) | E11: Velocity safety guarantee | F11: — | G11: Needs Phase 6 (H1 env) | H11: — | I11: mj_mulM for torque-controlled joints
A12: 10 | B12: World Model | C12: 🔲 Todo | D12: CfC world model + imagination rollouts | E12: Prediction accuracy | F12: — | G12: Needs Phase 3b policy | H12: — | I12: Original v12 Step 2/3 vision

Sheet Capabilities
A1: # | B1: Category | C1: Capability | D1: Status | E1: Phase Required | F1: I/O Pattern | G1: Robot(s) | H1: Obs Dims | I1: Act Dims | J1: Validated On | K1: Notes
A2: 1 | B2: Locomotion | C2: Forward walk | D2: ✅ Done | E2: 3a/3b | F2: Velocity cmd → PD targets | G2: Go1 | H2: 48 | I2: 12 | J2: Colab H100, vx=1.0 | K2: Reward 27.4, walking gait confirmed
A3: 2 | B3: Locomotion | C3: Velocity tracking (variable speed) | D3: ✅ Done | E3: 3a/3b | F3: Velocity cmd → PD targets | G3: Go1 | H3: 48 | I3: 12 | J3: Colab H100 | K3: Tested vx=0.5, 1.0, 1.5
A4: 3 | B4: Locomotion | C4: Omnidirectional walk | D4: ✅ Done | E4: 3a/3b | F4: Velocity cmd → PD targets | G4: Go1 | H4: 48 | I4: 12 | J4: Colab H100, vy+yaw | K4: Aggressive cmd: vx=1.5, vy=0.5, yaw=1.0
A5: 4 | B5: Locomotion | C5: Backward walk | D5: 🟡 Partial | E5: 3b (eval only) | F5: Velocity cmd → PD targets | G5: Go1 | H5: 48 | I5: 12 | J5: — | K5: Same policy, needs vx<0 eval
A6: 5 | B6: Locomotion | C6: Lateral walk (L/R) | D6: 🟡 Partial | E6: 3b (eval only) | F6: Velocity cmd → PD targets | G6: Go1 | H6: 48 | I6: 12 | J6: — | K6: Same policy, needs vy-only eval
A7: 6 | B7: Locomotion | C7: Turning in place | D7: 🟡 Partial | E7: 3b (eval only) | F7: Velocity cmd → PD targets | G7: Go1 | H7: 48 | I7: 12 | J7: — | K7: Same policy, needs yaw-only eval
A8: 7 | B8: Locomotion | C8: Heading tracking | D8: 🟡 Partial | E8: 3b (eval only) | F8: Velocity cmd → PD targets | G8: Go1 | H8: 48 | I8: 12 | J8: — | K8: Yaw command already supported
A9: 8 | B9: Locomotion | C9: Trotting | D9: 🔲 Todo | E9: 7 (MoE) | F9: Gait cmd + vel → PD targets | G9: Go1 | H9: 48+ | I9: 12 | J9: — | K9: Needs gait conditioning or MoE expert
A10: 9 | B10: Locomotion | C10: Bounding | D10: 🔲 Todo | E10: 7 (MoE) | F10: Gait cmd + vel → PD targets | G10: Go1 | H10: 48+ | I10: 12 | J10: — | K10: Walk These Ways style
A11: 10 | B11: Locomotion | C11: Galloping | D11: 🔲 Todo | E11: 7 (MoE) | F11: Gait cmd + vel → PD targets | G11: Go1 | H11: 48+ | I11: 12 | J11: —
A12: 11 | B12: Locomotion | C12: Pacing | D12: 🔲 Todo | E12: 7 (MoE) | F12: Gait cmd + vel → PD targets | G12: Go1 | H12: 48+ | I12: 12 | J12: —
A13: 12 | B13: Locomotion | C13: Pronking | D13: 🔲 Todo | E13: 7 (MoE) | F13: Gait cmd + vel → PD targets | G13: Go1 | H13: 48+ | I13: 12 | J13: —
A14: 13 | B14: Locomotion | C14: Stair ascent | D14: 🔲 Todo | E14: 5+6 | F14: Vel + height scan → PD targets | G14: Go1/H1 | H14: 48+187 | I14: 12 | J14: — | K14: Rough terrain env, height scan obs
A15: 14 | B15: Locomotion | C15: Stair descent | D15: 🔲 Todo | E15: 5+6 | F15: Vel + height scan → PD targets | G15: Go1/H1 | H15: 48+187 | I15: 12 | J15: —
A16: 15 | B16: Locomotion | C16: Slope ascent | D16: 🔲 Todo | E16: 5+6 | F16: Vel + height scan → PD targets | G16: Go1/H1 | H16: 48+187 | I16: 12 | J16: —
A17: 16 | B17: Locomotion | C17: Slope descent | D17: 🔲 Todo | E17: 5+6 | F17: Vel + height scan → PD targets | G17: Go1/H1 | H17: 48+187 | I17: 12 | J17: —
A18: 17 | B18: Locomotion | C18: Step over obstacle | D18: 🔲 Todo | E18: 5+6 | F18: Vel + height scan → PD targets | G18: Go1/H1 | H18: 48+187 | I18: 12 | J18: — | K18: Parkour-style, ETH approach
A19: 18 | B19: Locomotion | C19: Crawling / crouching | D19: 🔲 Todo | E19: 5 | F19: Vel + height cmd → PD targets | G19: Go1/H1 | H19: 48+ | I19: 12 | J19: — | K19: Body height as additional command
A20: 19 | B20: Balance | C20: Static balance (flat) | D20: 🟡 Partial | E20: 3b (implicit) | F20: — (emergent) | G20: Go1 | H20: 48 | I20: 12 | J20: — | K20: Trained via DR, not explicitly tested
A21: 20 | B21: Balance | C21: Dynamic balance (moving) | D21: 🟡 Partial | E21: 3b (implicit) | F21: — (emergent) | G21: Go1 | H21: 48 | I21: 12 | J21: —
A22: 21 | B22: Balance | C22: Push recovery (lateral) | D22: 🔲 Todo | E22: 5 | F22: — (emergent from DR) | G22: Go1/H1 | H22: 48 | I22: 12 | J22: — | K22: Needs push perturbation eval
A23: 22 | B23: Balance | C23: Push recovery (frontal) | D23: 🔲 Todo | E23: 5 | F23: — (emergent from DR) | G23: Go1/H1 | H23: 48 | I23: 12 | J23: —
A24: 23 | B24: Balance | C24: Push recovery (rear) | D24: 🔲 Todo | E24: 5 | F24: — (emergent from DR) | G24: Go1/H1 | H24: 48 | I24: 12 | J24: —
A25: 24 | B25: Balance | C25: Fall prevention | D25: 🔲 Todo | E25: 5 | F25: Body CBF (roll/pitch limit) | G25: Go1/H1 | H25: 48 | I25: 12 | J25: — | K25: Phase 5 body-level CBF
A26: 25 | B26: Balance | C26: Fall recovery (prone) | D26: 🔲 Todo | E26: 6+7 | F26: Orientation → standup torques | G26: H1 | H26: 48+ | I26: 19+ | J26: — | K26: Humanoid standup task
A27: 26 | B27: Balance | C27: Fall recovery (supine) | D27: 🔲 Todo | E27: 6+7 | F27: Orientation → standup torques | G27: H1 | H27: 48+ | I27: 19+ | J27: —
A28: 27 | B28: Balance | C28: Single-leg balance | D28: 🔲 Todo | E28: 5 | F28: — (emergent) | G28: Go1/H1 | H28: 48 | I28: 12 | J28: —
A29: 28 | B29: Balance | C29: Balance on uneven terrain | D29: 🔲 Todo | E29: 5+6 | F29: Proprioception → reactive | G29: Go1/H1 | H29: 48+187 | I29: 12 | J29: — | K29: Rough terrain env
A30: 29 | B30: Balance | C30: Balance under payload | D30: 🔲 Todo | E30: 5+7 | F30: — (CfC adapts via h) | G30: Go1/H1 | H30: 48 | I30: 12 | J30: — | K30: RMA-style adaptation
A31: 30 | B31: Balance | C31: Balance during manipulation | D31: 🔲 Todo | E31: 6+7 | F31: Whole-body coordination | G31: H1 | H31: 48+ | I31: 19+ | J31: —
A32: 31 | B32: Posture | C32: Stand from sit | D32: 🔲 Todo | E32: 6 | F32: Posture cmd → joint trajectory | G32: H1 | H32: 48+ | I32: 19+ | J32: — | K32: Humanoid only
A33: 32 | B33: Posture | C33: Sit from stand | D33: 🔲 Todo | E33: 6 | F33: Posture cmd → joint trajectory | G33: H1 | H33: 48+ | I33: 19+ | J33: —
A34: 33 | B34: Posture | C34: Crouch | D34: 🔲 Todo | E34: 5 | F34: Height cmd → PD targets | G34: Go1/H1 | H34: 48+ | I34: 12 | J34: — | K34: Body height as command
A35: 34 | B35: Posture | C35: Kneel | D35: 🔲 Todo | E35: 6 | F35: Posture cmd → joint trajectory | G35: H1 | H35: 48+ | I35: 19+ | J35: — | K35: Humanoid only
A36: 35 | B36: Posture | C36: Lean (fwd/bwd/lateral) | D36: 🔲 Todo | E36: 5 | F36: Torso orient cmd → PD targets | G36: Go1/H1 | H36: 48+ | I36: 12 | J36: —
A37: 36 | B37: Posture | C37: Torso orientation control | D37: 🔲 Todo | E37: 5 | F37: Torso orient cmd → PD targets | G37: Go1/H1 | H37: 48+ | I37: 12 | J37: —
A38: 37 | B38: Posture | C38: Height adjustment | D38: 🔲 Todo | E38: 5 | F38: Height cmd → PD targets | G38: Go1/H1 | H38: 48+ | I38: 12 | J38: —
A39: 38 | B39: Posture | C39: Weight shifting | D39: 🔲 Todo | E39: 5 | F39: CoM cmd → PD targets | G39: Go1/H1 | H39: 48+ | I39: 12 | J39: —
A40: 39 | B40: Manipulation | C40: End-effector position tracking | D40: 🔲 Todo | E40: 6+9 | F40: EE pos cmd → arm torques | G40: H1 | H40: 48+ | I40: 19+ | J40: — | K40: Requires H1 arms
...

Sheet Dashboard
A1: SOMA v13 — Progress Dashboard
A3: Overall Progress
A4: Status | B4: Count | C4: % of Total
A5: ✅ Done | B5: =COUNTIF(Capabilities!D:D,"*Done*") -> 6 | C5: =B5/B8 -> 0.075949367
A6: 🟡 Partial | B6: =COUNTIF(Capabilities!D:D,"*Partial*") -> 10 | C6: =B6/B8 -> 0.12658228
A7: 🔲 Todo | B7: =COUNTIF(Capabilities!D:D,"*Todo*") -> 63 | C7: =B7/B8 -> 0.79746835
A8: Total | B8: =SUM(B5:B7) -> 79 | C8: =B8/B8 -> 1
A10: Progress by Category
A11: Category | B11: Total | C11: Done | D11: Partial | E11: Todo | F11: % Complete
A12: Locomotion | B12: =COUNTIF(Capabilities!B:B,"Locomotion") -> 18 | C12: =COUNTIFS(Capabilities!B:B,"Locomotion",Capabilities!D:D,"*Done*") -> 3 | D12: =COUNTIFS(Capabilities!B:B,"Locomotion",Capabilities!D:D,"*Partial*") -> 4 | E12: =COUNTIFS(Capabilities!B:B,"Locomotion",Capabilities!D:D,"*Todo*") -> 11 | F12: =(C12+D12*0.5)/B12 -> 0.27777778
A13: Balance | B13: =COUNTIF(Capabilities!B:B,"Balance") -> 12 | C13: =COUNTIFS(Capabilities!B:B,"Balance",Capabilities!D:D,"*Done*") -> 0 | D13: =COUNTIFS(Capabilities!B:B,"Balance",Capabilities!D:D,"*Partial*") -> 2 | E13: =COUNTIFS(Capabilities!B:B,"Balance",Capabilities!D:D,"*Todo*") -> 10 | F13: =(C13+D13*0.5)/B13 -> 0.083333333
A14: Posture | B14: =COUNTIF(Capabilities!B:B,"Posture") -> 8 | C14: =COUNTIFS(Capabilities!B:B,"Posture",Capabilities!D:D,"*Done*") -> 0 | D14: =COUNTIFS(Capabilities!B:B,"Posture",Capabilities!D:D,"*Partial*") -> 0 | E14: =COUNTIFS(Capabilities!B:B,"Posture",Capabilities!D:D,"*Todo*") -> 8 | F14: =(C14+D14*0.5)/B14 -> 0
A15: Manipulation | B15: =COUNTIF(Capabilities!B:B,"Manipulation") -> 15 | C15: =COUNTIFS(Capabilities!B:B,"Manipulation",Capabilities!D:D,"*Done*") -> 0 | D15: =COUNTIFS(Capabilities!B:B,"Manipulation",Capabilities!D:D,"*Partial*") -> 0 | E15: =COUNTIFS(Capabilities!B:B,"Manipulation",Capabilities!D:D,"*Todo*") -> 15 | F15: =(C15+D15*0.5)/B15 -> 0
A16: Compliance | B16: =COUNTIF(Capabilities!B:B,"Compliance") -> 5 | C16: =COUNTIFS(Capabilities!B:B,"Compliance",Capabilities!D:D,"*Done*") -> 0 | D16: =COUNTIFS(Capabilities!B:B,"Compliance",Capabilities!D:D,"*Partial*") -> 0 | E16: =COUNTIFS(Capabilities!B:B,"Compliance",Capabilities!D:D,"*Todo*") -> 5 | F16: =(C16+D16*0.5)/B16 -> 0
A17: Whole-Body | B17: =COUNTIF(Capabilities!B:B,"Whole-Body") -> 5 | C17: =COUNTIFS(Capabilities!B:B,"Whole-Body",Capabilities!D:D,"*Done*") -> 0 | D17: =COUNTIFS(Capabilities!B:B,"Whole-Body",Capabilities!D:D,"*Partial*") -> 0 | E17: =COUNTIFS(Capabilities!B:B,"Whole-Body",Capabilities!D:D,"*Todo*") -> 5 | F17: =(C17+D17*0.5)/B17 -> 0
A18: Robustness | B18: =COUNTIF(Capabilities!B:B,"Robustness") -> 8 | C18: =COUNTIFS(Capabilities!B:B,"Robustness",Capabilities!D:D,"*Done*") -> 0 | D18: =COUNTIFS(Capabilities!B:B,"Robustness",Capabilities!D:D,"*Partial*") -> 3 | E18: =COUNTIFS(Capabilities!B:B,"Robustness",Capabilities!D:D,"*Todo*") -> 5 | F18: =(C18+D18*0.5)/B18 -> 0.1875
A19: SOMA-Only | B19: =COUNTIF(Capabilities!B:B,"SOMA-Only") -> 8 | C19: =COUNTIFS(Capabilities!B:B,"SOMA-Only",Capabilities!D:D,"*Done*") -> 3 | D19: =COUNTIFS(Capabilities!B:B,"SOMA-Only",Capabilities!D:D,"*Partial*") -> 1 | E19: =COUNTIFS(Capabilities!B:B,"SOMA-Only",Capabilities!D:D,"*Todo*") -> 4 | F19: =(C19+D19*0.5)/B19 -> 0.4375
A21: Key Metrics Achieved
A22: Metric | B22: Value | C22: Phase | D22: Significance
A23: CfC vs MLP reward | B23: 2.38x (27.4 vs 11.5) | C23: 3a | D23: First CfC quadruped locomotion
A24: CBF unit tests | B24: 7/7 passing | C24: 4 | D24: Provable safety certificate
A25: CBF throughput (compiled) | B25: 84 kHz | C25: 4 | D25: 8.4x over 10kHz requirement
A26: CBF batch throughput | B26: 1.13B calls/sec | C26: 4 | D26: Training-scale safety
A27: Reward loss (CBF on) | B27: 0% forward, 1.1% aggressive | C27: 4 | D27: Zero performance degradation
A28: CBF compute per env | B28: 0.01 μs | C28: 4 | D28: 10,000x headroom for 10kHz
A29: Real joint inertia M | B29: 0.023 kg·m² | C29: 4b | D29: Discovered M_EFF was 26x wrong
A30: Policy inference + CBF | B30: < 1 μs total | C30: 3+4 | D30: Real-time on any hardware

Sheet IO Patterns
A1: Pattern # | B1: Name | C1: Command Input | D1: Observation | E1: Action Output | F1: Capabilities Covered | G1: Status | H1: Robot(s)
A2: P1 | B2: Velocity Locomotion | C2: vx, vy, yaw_rate (3D) | D2: q_rel(12), qdot(12), gravity(3), gyro(3), prev_action(12), cmd(3), phase(2)=~48D | E2: PD targets (12D) | F2: Forward/back/lateral walk, turning, velocity tracking, heading, omnidirectional (8 capabilities) | G2: ✅ Proven | H2: Go1
A3: P2 | B3: Gait-Conditioned Locomotion | C3: vx, vy, yaw + gait_params(8D) | D3: P1 obs + gait_phase(2), gait_freq(1)=~51D | E3: PD targets (12D) | F3: Trot, bound, gallop, pace, pronk (5 capabilities) | G3: 🔲 Todo | H3: Go1
A4: P3 | B4: Terrain Locomotion | C4: vx, vy, yaw (3D) | D4: P1 obs + height_scan(187D)=~235D | E4: PD targets (12D) | F4: Stairs, slopes, obstacles, uneven terrain (6 capabilities) | G4: 🔲 Todo | H4: Go1/H1
A5: P4 | B5: Posture Control | C5: body_height, torso_rpy (4D) | D5: P1 obs + body_pose(6D)=~54D | E5: PD targets (12-19D) | F5: Crouch, lean, height adjust, weight shift, stand/sit (8 capabilities) | G5: 🔲 Todo | H5: Go1/H1
A6: P5 | B6: Balance / Recovery | C6: — (reactive, no explicit cmd) | D6: P1 obs + contact_forces(12D)=~60D | E6: PD targets (12-19D) | F6: Push recovery, fall prevention, single-leg, payload balance (10 capabilities) | G6: 🟡 Implicit | H6: Go1/H1
A7: P6 | B7: Arm Manipulation | C7: EE_pose_target (6D) + grip_cmd (1D) | D7: P1 obs + arm_q(7D), arm_qdot(7D), EE_pos(3D), EE_force(3D)=~68D | E7: Arm torques or PD (7-19D) | F7: EE tracking, force contact, insertion, handover (7 capabilities) | G7: 🔲 Todo | H7: H1
A8: P7 | B8: Dexterous Hand | C8: grip_type(1D) + finger_targets(16D) | D8: P6 obs + finger_q(16D), finger_qdot(16D), tactile(~48D)=~148D | E8: Finger torques (16D) | F8: Pinch, power grip, in-hand rotation, tool use (7 capabilities) | G8: 🔲 Todo | H8: H1+hands
A9: P8 | B9: Loco-Manipulation | C9: vel(3D) + EE_target(6D) + grip(1D) | D9: P1 + P6 obs combined=~80D | E9: Whole-body (19-25D) | F9: Walk+reach, walk+carry, stand+manipulate (5 capabilities) | G9: 🔲 Todo | H9: H1
A10: P9 | B10: Variable Impedance | C10: q_target(ND) + Kp(ND) + Kd(ND) | D10: P1 obs + contact_forces=~60D | E10: q_target + Kp + Kd (3×N D) | F10: Variable stiffness, compliance, force limiting (5 capabilities) | G10: 🔲 Todo | H10: H1
A11: P10 | B11: Robustness (DR) | C11: — (training condition, not I/O) | D11: Standard obs (varies by task) | E11: Standard action (varies) | F11: Mass/friction/motor/sensor/latency tolerance (8 capabilities) | G11: 🟡 Partial | H11: All
A12: P11 | B12: SOMA Properties | C12: — (architectural, not I/O) | D12: — | E12: — | F12: O(1), WCET, CBF, freq invariance, transfer, deploy (8 capabilities) | G12: 🟡 Partial | H12: All

Sheet Unlock Gates
A1: Gate | B1: Name | C1: Phases Required | D1: Capabilities Unlocked | E1: Count | F1: Effort Estimate | G1: Dependencies | H1: Priority
A2: G1 | B2: Multi-Terrain Locomotion | C2: 5 (Body CBFs) | D2: Stairs, slopes, obstacles, crawl, terrain balance, push recovery, posture basics | E2: ~15 | F2: 2-3 days (training runs) | G2: Rough terrain env setup | H2: HIGH — demo impact
A3: G2 | B3: Multi-Robot + MoE | C3: 6 + 7 | D3: Cross-robot transfer, multi-gait, MoE interpretability, fall recovery | E3: ~12 | F3: 1-2 weeks | G3: H1 env, MoE architecture | H3: HIGH — investor story
A4: G3 | B4: Humanoid Manipulation | C4: 6 + 9 | D4: All 15 manipulation, 5 compliance, 5 whole-body, H1 torque CBF | E4: ~30 | F4: 3-4 weeks | G4: H1 hands, force sensing, torque control | H4: MEDIUM — biggest capability gap
A5: G4 | B5: Deployment Package | C5: 8 | D5: Freq invariance, sub-500KB, CPU-only, full DR validation | E5: ~10 | F5: 1 week | G5: Stable policy from G1-G3 | H5: HIGH — demo ready
